[2022-03-05 23:18:49,431] [log.py:230] [log:log_response] [ERROR]- Internal Server Error: /users/register/
Traceback (most recent call last):
  File "D:\Python37\lib\site-packages\django\core\handlers\exception.py", line 47, in inner
    response = get_response(request)
  File "D:\Python37\lib\site-packages\django\core\handlers\base.py", line 181, in _get_response
    response = wrapped_callback(request, *callback_args, **callback_kwargs)
  File "D:\Python37\lib\site-packages\django\views\generic\base.py", line 70, in view
    return self.dispatch(request, *args, **kwargs)
  File "D:\Python37\lib\site-packages\django\views\generic\base.py", line 98, in dispatch
    return handler(request, *args, **kwargs)
  File "D:\Django_aijia\my_aijia\my_aijia/apps\users\views.py", line 35, in post
    print('哈哈'+re_checkbox)
TypeError: can only concatenate str (not "NoneType") to str
[2022-03-05 23:18:49,436] [basehttp.py:161] [basehttp:log_message] [ERROR]- "POST /users/register/ HTTP/1.1" 500 81874
[2022-03-05 23:20:55,449] [log.py:230] [log:log_response] [ERROR]- Internal Server Error: /users/register/
Traceback (most recent call last):
  File "D:\Python37\lib\site-packages\django\core\handlers\exception.py", line 47, in inner
    response = get_response(request)
  File "D:\Python37\lib\site-packages\django\core\handlers\base.py", line 181, in _get_response
    response = wrapped_callback(request, *callback_args, **callback_kwargs)
  File "D:\Python37\lib\site-packages\django\views\generic\base.py", line 70, in view
    return self.dispatch(request, *args, **kwargs)
  File "D:\Python37\lib\site-packages\django\views\generic\base.py", line 98, in dispatch
    return handler(request, *args, **kwargs)
  File "D:\Django_aijia\my_aijia\my_aijia/apps\users\views.py", line 47, in post
    login(request, user)
  File "D:\Python37\lib\site-packages\django\contrib\auth\__init__.py", line 103, in login
    if _get_user_session_key(request) != user.pk or (
AttributeError: 'bool' object has no attribute 'pk'
[2022-03-05 23:20:55,454] [basehttp.py:161] [basehttp:log_message] [ERROR]- "POST /users/register/ HTTP/1.1" 500 86291
